ERROR:root:Webserver Fail
Traceback (most recent call last):
  File "Front.py", line 35, in main
    cursor.execute(sql)
  File "/usr/local/lib/python3.4/dist-packages/pymysql/cursors.py", line 166, in execute
    result = self._query(query)
  File "/usr/local/lib/python3.4/dist-packages/pymysql/cursors.py", line 322, in _query
    conn.query(q)
  File "/usr/local/lib/python3.4/dist-packages/pymysql/connections.py", line 856, in query
    self._affected_rows = self._read_query_result(unbuffered=unbuffered)
  File "/usr/local/lib/python3.4/dist-packages/pymysql/connections.py", line 1057, in _read_query_result
    result.read()
  File "/usr/local/lib/python3.4/dist-packages/pymysql/connections.py", line 1340, in read
    first_packet = self.connection._read_packet()
  File "/usr/local/lib/python3.4/dist-packages/pymysql/connections.py", line 987, in _read_packet
    packet_header = self._read_bytes(4)
  File "/usr/local/lib/python3.4/dist-packages/pymysql/connections.py", line 1033, in _read_bytes
    CR.CR_SERVER_LOST, "Lost connection to MySQL server during query")
pymysql.err.OperationalError: (2013, 'Lost connection to MySQL server during query')
ERROR:root:Webserver Fail
Traceback (most recent call last):
  File "Front.py", line 35, in main
    cursor.execute(sql)
  File "/usr/local/lib/python3.4/dist-packages/pymysql/cursors.py", line 166, in execute
    result = self._query(query)
  File "/usr/local/lib/python3.4/dist-packages/pymysql/cursors.py", line 322, in _query
    conn.query(q)
  File "/usr/local/lib/python3.4/dist-packages/pymysql/connections.py", line 855, in query
    self._execute_command(COMMAND.COM_QUERY, sql)
  File "/usr/local/lib/python3.4/dist-packages/pymysql/connections.py", line 1071, in _execute_command
    raise err.InterfaceError("(0, '')")
pymysql.err.InterfaceError: (0, '')
ERROR:root:Webserver Fail
Traceback (most recent call last):
  File "Front.py", line 35, in main
    cursor.execute(sql)
  File "/usr/local/lib/python3.4/dist-packages/pymysql/cursors.py", line 166, in execute
    result = self._query(query)
  File "/usr/local/lib/python3.4/dist-packages/pymysql/cursors.py", line 322, in _query
    conn.query(q)
  File "/usr/local/lib/python3.4/dist-packages/pymysql/connections.py", line 855, in query
    self._execute_command(COMMAND.COM_QUERY, sql)
  File "/usr/local/lib/python3.4/dist-packages/pymysql/connections.py", line 1071, in _execute_command
    raise err.InterfaceError("(0, '')")
pymysql.err.InterfaceError: (0, '')
ERROR:root:Webserver Fail
Traceback (most recent call last):
  File "Front.py", line 35, in main
    cursor.execute(sql)
  File "/usr/local/lib/python3.4/dist-packages/pymysql/cursors.py", line 166, in execute
    result = self._query(query)
  File "/usr/local/lib/python3.4/dist-packages/pymysql/cursors.py", line 322, in _query
    conn.query(q)
  File "/usr/local/lib/python3.4/dist-packages/pymysql/connections.py", line 855, in query
    self._execute_command(COMMAND.COM_QUERY, sql)
  File "/usr/local/lib/python3.4/dist-packages/pymysql/connections.py", line 1071, in _execute_command
    raise err.InterfaceError("(0, '')")
pymysql.err.InterfaceError: (0, '')
ERROR:root:Webserver Fail
Traceback (most recent call last):
  File "Front.py", line 35, in main
    cursor.execute(sql)
  File "/usr/local/lib/python3.4/dist-packages/pymysql/cursors.py", line 166, in execute
    result = self._query(query)
  File "/usr/local/lib/python3.4/dist-packages/pymysql/cursors.py", line 322, in _query
    conn.query(q)
  File "/usr/local/lib/python3.4/dist-packages/pymysql/connections.py", line 855, in query
    self._execute_command(COMMAND.COM_QUERY, sql)
  File "/usr/local/lib/python3.4/dist-packages/pymysql/connections.py", line 1071, in _execute_command
    raise err.InterfaceError("(0, '')")
pymysql.err.InterfaceError: (0, '')
